Workbook
Name ADC_att: Parameters!$C$40
Name ADC_exh: Parameters!$C$41
Name ADC_rol: Parameters!$C$42
Name Cred_full: Parameters!$C$25:$E$25
Name Cred_mature: Parameters!$C$26:$E$26
Name Disc_rate: Parameters!$C$18
Name Exp_ratio: Parameters!$C$11:$E$11
Name Ext_shock: Parameters!$C$34
Name Ext_tail: Parameters!$C$32:$E$32
Name Ext_taillag: Parameters!$C$33
Name Loss_trend: Parameters!$C$17
Name Plan_LR: Parameters!$C$24:$E$24
Name Val_rate_max: Parameters!$C$50
Name Val_rate_min: Parameters!$C$49
Name Val_ratio_max: Parameters!$C$48

Sheet Cover
B2: Northgate Mutual Insurance Society
B3: Commercial Motor - Unpaid Claim Liability and Reinsurance Model
B4: Reserving date: 31 December 2025 | All monetary amounts in GBP thousands (£000)
B6: Purpose | C6: Estimate the unpaid claim liability for the Commercial Motor account under three
C7: alternative reserving bases, test the result against a management-directed adverse
C8: scenario, and evaluate an Adverse Development Cover offered by the reinsurer.
B10: Contents
B11: Raw Data | C11: Source data as received, prior to any adjustment (Tables 1-3)
B12: Data Validation | C12: Defect detection, correction rules and validated triangles
B13: Parameters | C13: All model parameters and assumptions (Tables 4-10)
B14: Dev Factors | C14: Age-to-age factors, selections and cumulative development factors
B15: S1 Chain Ladder | C15: Base scenario 1 - Chain Ladder ultimates and reserves
B16: On-Level & Cred | C16: On-levelling, loss trend and credibility-weighted a priori loss ratios
B17: S2 Expected Claims | C17: Base scenario 2 - Expected Claims ultimates and reserves
B18: S3 BF | C18: Base scenario 3 - Bornhuetter-Ferguson ultimates and reserves
B19: Extension | C19: Extension scenario - tail factor and claims inflation shock, all three bases
B20: ADC | C20: Adverse Development Cover - layer analysis and break-even shock rate
B21: Summary | C21: Comparative results and charts
B22: Checks | C22: Consolidated check dashboard
B23: Audit Trail | C23: Full methodology, assumptions and check documentation
B25: Cell convention
B26: Blue text | C26: Hardcoded input or scenario lever - edit here
B27: Black text | C27: Formula calculated on this sheet
B28: Green text | C28: Link to another sheet in this workbook
B29: Yellow fill | C29: Key assumption set by management or judgement
B30: Green fill | C30: Check - must read OK
B31: Red fill | C31: Data defect identified by the validation rules
B33: Note | C33: The model contains no volatile functions, no macros and no external links.

Sheet Raw Data
B1: Raw Data - as received, before validation
B2: Source: Northgate Mutual claims administration system extract of 14 January 2026 (paid amounts) and finance system (premium and rate history). Received as a flat file and pasted unaltered.
B3: This sheet is deliberately left unadjusted. All corrections are made on the "Data Validation" sheet so that the audit path from source to model input is visible.
B5: Table 1: Raw cumulative paid claims by rating group (£000)
B6: Rows are accident years; columns are development age in months from the start of the accident year.
B8: Group A - Light commercial vehicles
B9: Accident year | C9: 12 months | D9: 24 months | E9: 36 months | F9: 48 months | G9: 60 months | H9: 72 months
B10: 2020 | C10: 960.7 | D10: 1755.3 | E10: 2087.5 | F10: 2271 | G10: 2344.6 | H10: 2432.5
B11: 2021 | C11: 951.5 | D11: 1752.7 | E11: 2106 | F11: 2326.4 | G11: 2437.7
B12: 2022 | C12: 1459.8 | D12: 2147.4 | E12: 2643.7 | F12: 2612
B13: 2023 | C13: 1306.2 | D13: n/a | E13: 2705.1
B14: 2024 | C14: 1423.4 | D14: 2305.4
B15: 2025 | C15: 1525.9
B18: Group B - Heavy goods vehicles
B19: Accident year | C19: 12 months | D19: 24 months | E19: 36 months | F19: 48 months | G19: 60 months | H19: 72 months
B20: 2020 | C20: 630.7 | D20: 1200.1 | E20: 1455.9 | F20: 1629.2 | G20: 1815 | H20: 1851.3
B21: 2021 | C21: 681.6 | D21: 1386.2 | F21: 2000.7 | G21: 2106.4
B22: 2022 | C22: 778.7 | D22: 1456.6 | E22: 1941.2 | F22: 2119.6
B23: 2023 | C23: 757.7 | D23: 1549 | E23: 1982.1
B24: 2024 | C24: 960.5 | D24: 1694.4
B25: 2025 | C25: 907
B28: Group C - Specialist haulage
B29: Accident year | C29: 12 months | D29: 24 months | E29: 36 months | F29: 48 months | G29: 60 months | H29: 72 months
B30: 2020 | C30: 321.3 | D30: 6865 | E30: 959.7 | F30: 1162.1 | G30: 1241.6 | H30: 1300.2
B31: 2021 | C31: 388 | D31: 799.2 | E31: 1092 | F31: 1318.5 | G31: 1409.9
B32: 2022 | C32: 457.3 | D32: 1002.9 | E32: 1336.5 | F32: 1598
B33: 2023 | C33: 450.7 | D33: 947.8 | E33: 1260.1
B34: 2024 | C34: 491.9 | D34: 991.2
B35: 2025 | C35: 469
B38: Table 2: Raw reported claim counts by rating group
B39: Counts of reported claims, used only to set credibility weights. Source: claims administration system.
B40: Accident year | C40: Group A | D40: Group B | E40: Group C
B41: 2020 | C41: 300 | D41: 145 | E41: 60
B42: 2021 | C42: 315 | D42: 150 | E42: 64
B43: 2022 | C43: 325 | D43: 155 | E43: 68
B44: 2023 | C44: 340 | D44: 160 | E44: 72
B45: 2024 | C45: 360 | D45: 175 | E45: 80
B46: 2025 | C46: 380 | D46: 190 | E46: 86
B49: Table 3: Raw history of rate changes by rating group
B50: Average rate change achieved on renewal, effective 1 January of the accident year shown. Source: underwriting rate monitoring return.
...

Sheet Data Validation
B1: Data Validation - detection and correction of defects in the source data
B2: Satisfies Part 1 requirement 3 (data validation and sensitivity checks on the input data).
B4: Validation rules applied to the raw paid triangles
B5: R1 | C5: Every in-triangle cell must contain a number. Blank cells and text entries are flagged as missing. The link from a source cell preserves a genuine blank as blank, rather than letting it read through as zero, so that a missing entry is caught here and not mistaken for a real, reported zero later in rule R3.
B6: R2 | C6: Cumulative paid claims cannot fall as development age increases, because the account carries no salvage or subrogation recoveries (see Parameters, Table 10). A cell at or below its predecessor is flagged.
B7: R3 | C7: A link ratio above the outlier bound Val_ratio_max is implausible for this class and is flagged as a probable keying error. A zero or negative predecessor is flagged directly without attempting the division, since the ratio is undefined in that case.
B8: R4 | C8: Where the predecessor cell is itself flagged, no ratio test is applied to the current cell, so that a single defect is not double-counted. The defect does however cascade: the successor of a corrupted cell is tested against the corrupted value and may be flagged in turn.
B9: R5 | C9: Rate changes outside the range Val_rate_min to Val_rate_max are flagged and corrected manually against the underwriting rate monitoring return.
B11: Correction rule
C12: A flagged cell is replaced by the preceding validated cell multiplied by the volume-weighted average link ratio for that development step, computed from clean cells only. This preserves the observed development shape of the group without importing the defect.
C13: Cells at development age 12 months have no predecessor and cannot be corrected this way; check C4 confirms that no such cell is flagged.
B15: Group A - Light commercial vehicles
C16: Raw as received (£000) | J16: Defect flags (1 = flagged) | Q16: Clean numeric values (£000) | X16: Validated cumulative paid (£000)
B17: Accident year | C17: 12 | D17: 24 | E17: 36 | F17: 48 | G17: 60 | H17: 72 | J17: 12 | K17: 24 | L17: 36 | M17: 48 | N17: 60 | O17: 72 | Q17: 12 | R17: 24 | S17: 36 | T17: 48 | U17: 60 | V17: 72 | X17: 12 | Y17: 24 | Z17: 36 | AA17: 48 | AB17: 60 | AC17: 72
B18: 2020 | C18: =IF('Raw Data'!C10="","",'Raw Data'!C10) -> 960.7 | D18: =IF('Raw Data'!D10="","",'Raw Data'!D10) -> 1755.3 | E18: =IF('Raw Data'!E10="","",'Raw Data'!E10) -> 2087.5 | F18: =IF('Raw Data'!F10="","",'Raw Data'!F10) -> 2271 | G18: =IF('Raw Data'!G10="","",'Raw Data'!G10) -> 2344.6 | H18: =IF('Raw Data'!H10="","",'Raw Data'!H10) -> 2432.5 | J18: =IF(ISNUMBER(C18),0,1) -> 0 | K18: =IF(NOT(ISNUMBER(D18)),1,IF(NOT(ISNUMBER(C18)),0,IF(OR(D18<=C18,IF(C18<=0,TRUE(),D18/C18>Val_ratio_max)),1,0))) -> 0 | L18: =IF(NOT(ISNUMBER(E18)),1,IF(NOT(ISNUMBER(D18)),0,IF(OR(E18<=D18,IF(D18<=0,TRUE(),E18/D18>Val_ratio_max)),1,0))) -> 0 | M18: =IF(NOT(ISNUMBER(F18)),1,IF(NOT(ISNUMBER(E18)),0,IF(OR(F18<=E18,IF(E18<=0,TRUE(),F18/E18>Val_ratio_max)),1,0))) -> 0 | N18: =IF(NOT(ISNUMBER(G18)),1,IF(NOT(ISNUMBER(F18)),0,IF(OR(G18<=F18,IF(F18<=0,TRUE(),G18/F18>Val_ratio_max)),1,0))) -> 0 | O18: =IF(NOT(ISNUMBER(H18)),1,IF(NOT(ISNUMBER(G18)),0,IF(OR(H18<=G18,IF(G18<=0,TRUE(),H18/G18>Val_ratio_max)),1,0))) -> 0 | Q18: =IF(J18=1,0,IF(ISNUMBER(C18),C18,0)) -> 960.7 | R18: =IF(K18=1,0,IF(ISNUMBER(D18),D18,0)) -> 1755.3 | S18: =IF(L18=1,0,IF(ISNUMBER(E18),E18,0)) -> 2087.5 | T18: =IF(M18=1,0,IF(ISNUMBER(F18),F18,0)) -> 2271 | U18: =IF(N18=1,0,IF(ISNUMBER(G18),G18,0)) -> 2344.6 | V18: =IF(O18=1,0,IF(ISNUMBER(H18),H18,0)) -> 2432.5 | X18: =IF(J18=0,C18,"CHECK C4") -> 960.7 | Y18: =IF(K18=0,D18,X18*R$25) -> 1755.3 | Z18: =IF(L18=0,E18,Y18*S$25) -> 2087.5 | AA18: =IF(M18=0,F18,Z18*T$25) -> 2271 | AB18: =IF(N18=0,G18,AA18*U$25) -> 2344.6 | AC18: =IF(O18=0,H18,AB18*V$25) -> 2432.5
B19: 2021 | C19: =IF('Raw Data'!C11="","",'Raw Data'!C11) -> 951.5 | D19: =IF('Raw Data'!D11="","",'Raw Data'!D11) -> 1752.7 | E19: =IF('Raw Data'!E11="","",'Raw Data'!E11) -> 2106 | F19: =IF('Raw Data'!F11="","",'Raw Data'!F11) -> 2326.4 | G19: =IF('Raw Data'!G11="","",'Raw Data'!G11) -> 2437.7 | J19: =IF(ISNUMBER(C19),0,1) -> 0 | K19: =IF(NOT(ISNUMBER(D19)),1,IF(NOT(ISNUMBER(C19)),0,IF(OR(D19<=C19,IF(C19<=0,TRUE(),D19/C19>Val_ratio_max)),1,0))) -> 0 | L19: =IF(NOT(ISNUMBER(E19)),1,IF(NOT(ISNUMBER(D19)),0,IF(OR(E19<=D19,IF(D19<=0,TRUE(),E19/D19>Val_ratio_max)),1,0))) -> 0 | M19: =IF(NOT(ISNUMBER(F19)),1,IF(NOT(ISNUMBER(E19)),0,IF(OR(F19<=E19,IF(E19<=0,TRUE(),F19/E19>Val_ratio_max)),1,0))) -> 0 | N19: =IF(NOT(ISNUMBER(G19)),1,IF(NOT(ISNUMBER(F19)),0,IF(OR(G19<=F19,IF(F19<=0,TRUE(),G19/F19>Val_ratio_max)),1,0))) -> 0 | O19: 0 | Q19: =IF(J19=1,0,IF(ISNUMBER(C19),C19,0)) -> 951.5 | R19: =IF(K19=1,0,IF(ISNUMBER(D19),D19,0)) -> 1752.7 | S19: =IF(L19=1,0,IF(ISNUMBER(E19),E19,0)) -> 2106 | T19: =IF(M19=1,0,IF(ISNUMBER(F19),F19,0)) -> 2326.4 | U19: =IF(N19=1,0,IF(ISNUMBER(G19),G19,0)) -> 2437.7 | V19: 0 | X19: =IF(J19=0,C19,"CHECK C4") -> 951.5 | Y19: =IF(K19=0,D19,X19*R$25) -> 1752.7 | Z19: =IF(L19=0,E19,Y19*S$25) -> 2106 | AA19: =IF(M19=0,F19,Z19*T$25) -> 2326.4 | AB19: =IF(N19=0,G19,AA19*U$25) -> 2437.7
B20: 2022 | C20: =IF('Raw Data'!C12="","",'Raw Data'!C12) -> 1459.8 | D20: =IF('Raw Data'!D12="","",'Raw Data'!D12) -> 2147.4 | E20: =IF('Raw Data'!E12="","",'Raw Data'!E12) -> 2643.7 | F20: =IF('Raw Data'!F12="","",'Raw Data'!F12) -> 2612 | J20: =IF(ISNUMBER(C20),0,1) -> 0 | K20: =IF(NOT(ISNUMBER(D20)),1,IF(NOT(ISNUMBER(C20)),0,IF(OR(D20<=C20,IF(C20<=0,TRUE(),D20/C20>Val_ratio_max)),1,0))) -> 0 | L20: =IF(NOT(ISNUMBER(E20)),1,IF(NOT(ISNUMBER(D20)),0,IF(OR(E20<=D20,IF(D20<=0,TRUE(),E20/D20>Val_ratio_max)),1,0))) -> 0 | M20: =IF(NOT(ISNUMBER(F20)),1,IF(NOT(ISNUMBER(E20)),0,IF(OR(F20<=E20,IF(E20<=0,TRUE(),F20/E20>Val_ratio_max)),1,0))) -> 1 | N20: 0 | O20: 0 | Q20: =IF(J20=1,0,IF(ISNUMBER(C20),C20,0)) -> 1459.8 | R20: =IF(K20=1,0,IF(ISNUMBER(D20),D20,0)) -> 2147.4 | S20: =IF(L20=1,0,IF(ISNUMBER(E20),E20,0)) -> 2643.7 | T20: =IF(M20=1,0,IF(ISNUMBER(F20),F20,0)) -> 0 | U20: 0 | V20: 0 | X20: =IF(J20=0,C20,"CHECK C4") -> 1459.8 | Y20: =IF(K20=0,D20,X20*R$25) -> 2147.4 | Z20: =IF(L20=0,E20,Y20*S$25) -> 2643.7 | AA20: =IF(M20=0,F20,Z20*T$25) -> 2898.3299
B21: 2023 | C21: =IF('Raw Data'!C13="","",'Raw Data'!C13) -> 1306.2 | D21: =IF('Raw Data'!D13="","",'Raw Data'!D13) -> n/a | E21: =IF('Raw Data'!E13="","",'Raw Data'!E13) -> 2705.1 | J21: =IF(ISNUMBER(C21),0,1) -> 0 | K21: =IF(NOT(ISNUMBER(D21)),1,IF(NOT(ISNUMBER(C21)),0,IF(OR(D21<=C21,IF(C21<=0,TRUE(),D21/C21>Val_ratio_max)),1,0))) -> 1 | L21: =IF(NOT(ISNUMBER(E21)),1,IF(NOT(ISNUMBER(D21)),0,IF(OR(E21<=D21,IF(D21<=0,TRUE(),E21/D21>Val_ratio_max)),1,0))) -> 0 | M21: 0 | N21: 0 | O21: 0 | Q21: =IF(J21=1,0,IF(ISNUMBER(C21),C21,0)) -> 1306.2 | R21: =IF(K21=1,0,IF(ISNUMBER(D21),D21,0)) -> 0 | S21: =IF(L21=1,0,IF(ISNUMBER(E21),E21,0)) -> 2705.1 | T21: 0 | U21: 0 | V21: 0 | X21: =IF(J21=0,C21,"CHECK C4") -> 1306.2 | Y21: =IF(K21=0,D21,X21*R$25) -> 2168.4108 | Z21: =IF(L21=0,E21,Y21*S$25) -> 2705.1
B22: 2024 | C22: =IF('Raw Data'!C14="","",'Raw Data'!C14) -> 1423.4 | D22: =IF('Raw Data'!D14="","",'Raw Data'!D14) -> 2305.4 | J22: =IF(ISNUMBER(C22),0,1) -> 0 | K22: =IF(NOT(ISNUMBER(D22)),1,IF(NOT(ISNUMBER(C22)),0,IF(OR(D22<=C22,IF(C22<=0,TRUE(),D22/C22>Val_ratio_max)),1,0))) -> 0 | L22: 0 | M22: 0 | N22: 0 | O22: 0 | Q22: =IF(J22=1,0,IF(ISNUMBER(C22),C22,0)) -> 1423.4 | R22: =IF(K22=1,0,IF(ISNUMBER(D22),D22,0)) -> 2305.4 | S22: 0 | T22: 0 | U22: 0 | V22: 0 | X22: =IF(J22=0,C22,"CHECK C4") -> 1423.4 | Y22: =IF(K22=0,D22,X22*R$25) -> 2305.4
B23: 2025 | C23: =IF('Raw Data'!C15="","",'Raw Data'!C15) -> 1525.9 | J23: =IF(ISNUMBER(C23),0,1) -> 0 | K23: 0 | L23: 0 | M23: 0 | N23: 0 | O23: 0 | Q23: =IF(J23=1,0,IF(ISNUMBER(C23),C23,0)) -> 1525.9 | R23: 0 | S23: 0 | T23: 0 | U23: 0 | V23: 0 | X23: =IF(J23=0,C23,"CHECK C4") -> 1525.9
Q24: Volume-weighted average link ratio, computed from clean cells only (a cell pair is used only where both cells are unflagged, numeric and inside the triangle) | R24: 12-24 | S24: 24-36 | T24: 36-48 | U24: 48-60 | V24: 60-72
B25: Clean link ratio | J25: Cells flagged | M25: =SUM(J18:O23) -> 2 | R25: =SUMPRODUCT((R18:R23>0)*(Q18:Q23>0)*R18:R23)/SUMPRODUCT((R18:R23>0)*(Q18:Q23>0)*Q18:Q23) -> 1.6600909 | S25: =SUMPRODUCT((S18:S23>0)*(R18:R23>0)*S18:S23)/SUMPRODUCT((S18:S23>0)*(R18:R23>0)*R18:R23) -> 1.2089684 | T25: =SUMPRODUCT((T18:T23>0)*(S18:S23>0)*T18:T23)/SUMPRODUCT((T18:T23>0)*(S18:S23>0)*S18:S23) -> 1.0963157 | U25: =SUMPRODUCT((U18:U23>0)*(T18:T23>0)*U18:U23)/SUMPRODUCT((U18:U23>0)*(T18:T23>0)*T18:T23) -> 1.0402184 | V25: =SUMPRODUCT((V18:V23>0)*(U18:U23>0)*V18:V23)/SUMPRODUCT((V18:V23>0)*(U18:U23>0)*U18:U23) -> 1.0374904
B31: Group B - Heavy goods vehicles
C32: Raw as received (£000) | J32: Defect flags (1 = flagged) | Q32: Clean numeric values (£000) | X32: Validated cumulative paid (£000)
B33: Accident year | C33: 12 | D33: 24 | E33: 36 | F33: 48 | G33: 60 | H33: 72 | J33: 12 | K33: 24 | L33: 36 | M33: 48 | N33: 60 | O33: 72 | Q33: 12 | R33: 24 | S33: 36 | T33: 48 | U33: 60 | V33: 72 | X33: 12 | Y33: 24 | Z33: 36 | AA33: 48 | AB33: 60 | AC33: 72
B34: 2020 | C34: =IF('Raw Data'!C20="","",'Raw Data'!C20) -> 630.7 | D34: =IF('Raw Data'!D20="","",'Raw Data'!D20) -> 1200.1 | E34: =IF('Raw Data'!E20="","",'Raw Data'!E20) -> 1455.9 | F34: =IF('Raw Data'!F20="","",'Raw Data'!F20) -> 1629.2 | G34: =IF('Raw Data'!G20="","",'Raw Data'!G20) -> 1815 | H34: =IF('Raw Data'!H20="","",'Raw Data'!H20) -> 1851.3 | J34: =IF(ISNUMBER(C34),0,1) -> 0 | K34: =IF(NOT(ISNUMBER(D34)),1,IF(NOT(ISNUMBER(C34)),0,IF(OR(D34<=C34,IF(C34<=0,TRUE(),D34/C34>Val_ratio_max)),1,0))) -> 0 | L34: =IF(NOT(ISNUMBER(E34)),1,IF(NOT(ISNUMBER(D34)),0,IF(OR(E34<=D34,IF(D34<=0,TRUE(),E34/D34>Val_ratio_max)),1,0))) -> 0 | M34: =IF(NOT(ISNUMBER(F34)),1,IF(NOT(ISNUMBER(E34)),0,IF(OR(F34<=E34,IF(E34<=0,TRUE(),F34/E34>Val_ratio_max)),1,0))) -> 0 | N34: =IF(NOT(ISNUMBER(G34)),1,IF(NOT(ISNUMBER(F34)),0,IF(OR(G34<=F34,IF(F34<=0,TRUE(),G34/F34>Val_ratio_max)),1,0))) -> 0 | O34: =IF(NOT(ISNUMBER(H34)),1,IF(NOT(ISNUMBER(G34)),0,IF(OR(H34<=G34,IF(G34<=0,TRUE(),H34/G34>Val_ratio_max)),1,0))) -> 0 | Q34: =IF(J34=1,0,IF(ISNUMBER(C34),C34,0)) -> 630.7 | R34: =IF(K34=1,0,IF(ISNUMBER(D34),D34,0)) -> 1200.1 | S34: =IF(L34=1,0,IF(ISNUMBER(E34),E34,0)) -> 1455.9 | T34: =IF(M34=1,0,IF(ISNUMBER(F34),F34,0)) -> 1629.2 | U34: =IF(N34=1,0,IF(ISNUMBER(G34),G34,0)) -> 1815 | V34: =IF(O34=1,0,IF(ISNUMBER(H34),H34,0)) -> 1851.3 | X34: =IF(J34=0,C34,"CHECK C4") -> 630.7 | Y34: =IF(K34=0,D34,X34*R$41) -> 1200.1 | Z34: =IF(L34=0,E34,Y34*S$41) -> 1455.9 | AA34: =IF(M34=0,F34,Z34*T$41) -> 1629.2 | AB34: =IF(N34=0,G34,AA34*U$41) -> 1815 | AC34: =IF(O34=0,H34,AB34*V$41) -> 1851.3
B35: 2021 | C35: =IF('Raw Data'!C21="","",'Raw Data'!C21) -> 681.6 | D35: =IF('Raw Data'!D21="","",'Raw Data'!D21) -> 1386.2 | E35: =IF('Raw Data'!E21="","",'Raw Data'!E21) | F35: =IF('Raw Data'!F21="","",'Raw Data'!F21) -> 2000.7 | G35: =IF('Raw Data'!G21="","",'Raw Data'!G21) -> 2106.4 | J35: =IF(ISNUMBER(C35),0,1) -> 0 | K35: =IF(NOT(ISNUMBER(D35)),1,IF(NOT(ISNUMBER(C35)),0,IF(OR(D35<=C35,IF(C35<=0,TRUE(),D35/C35>Val_ratio_max)),1,0))) -> 0 | L35: =IF(NOT(ISNUMBER(E35)),1,IF(NOT(ISNUMBER(D35)),0,IF(OR(E35<=D35,IF(D35<=0,TRUE(),E35/D35>Val_ratio_max)),1,0))) -> 1 | M35: =IF(NOT(ISNUMBER(F35)),1,IF(NOT(ISNUMBER(E35)),0,IF(OR(F35<=E35,IF(E35<=0,TRUE(),F35/E35>Val_ratio_max)),1,0))) -> 0 | N35: =IF(NOT(ISNUMBER(G35)),1,IF(NOT(ISNUMBER(F35)),0,IF(OR(G35<=F35,IF(F35<=0,TRUE(),G35/F35>Val_ratio_max)),1,0))) -> 0 | O35: 0 | Q35: =IF(J35=1,0,IF(ISNUMBER(C35),C35,0)) -> 681.6 | R35: =IF(K35=1,0,IF(ISNUMBER(D35),D35,0)) -> 1386.2 | S35: =IF(L35=1,0,IF(ISNUMBER(E35),E35,0)) -> 0 | T35: =IF(M35=1,0,IF(ISNUMBER(F35),F35,0)) -> 2000.7 | U35: =IF(N35=1,0,IF(ISNUMBER(G35),G35,0)) -> 2106.4 | V35: 0 | X35: =IF(J35=0,C35,"CHECK C4") -> 681.6 | Y35: =IF(K35=0,D35,X35*R$41) -> 1386.2 | Z35: =IF(L35=0,E35,Y35*S$41) -> 1772.986 | AA35: =IF(M35=0,F35,Z35*T$41) -> 2000.7 | AB35: =IF(N35=0,G35,AA35*U$41) -> 2106.4
B36: 2022 | C36: =IF('Raw Data'!C22="","",'Raw Data'!C22) -> 778.7 | D36: =IF('Raw Data'!D22="","",'Raw Data'!D22) -> 1456.6 | E36: =IF('Raw Data'!E22="","",'Raw Data'!E22) -> 1941.2 | F36: =IF('Raw Data'!F22="","",'Raw Data'!F22) -> 2119.6 | J36: =IF(ISNUMBER(C36),0,1) -> 0 | K36: =IF(NOT(ISNUMBER(D36)),1,IF(NOT(ISNUMBER(C36)),0,IF(OR(D36<=C36,IF(C36<=0,TRUE(),D36/C36>Val_ratio_max)),1,0))) -> 0 | L36: =IF(NOT(ISNUMBER(E36)),1,IF(NOT(ISNUMBER(D36)),0,IF(OR(E36<=D36,IF(D36<=0,TRUE(),E36/D36>Val_ratio_max)),1,0))) -> 0 | M36: =IF(NOT(ISNUMBER(F36)),1,IF(NOT(ISNUMBER(E36)),0,IF(OR(F36<=E36,IF(E36<=0,TRUE(),F36/E36>Val_ratio_max)),1,0))) -> 0 | N36: 0 | O36: 0 | Q36: =IF(J36=1,0,IF(ISNUMBER(C36),C36,0)) -> 778.7 | R36: =IF(K36=1,0,IF(ISNUMBER(D36),D36,0)) -> 1456.6 | S36: =IF(L36=1,0,IF(ISNUMBER(E36),E36,0)) -> 1941.2 | T36: =IF(M36=1,0,IF(ISNUMBER(F36),F36,0)) -> 2119.6 | U36: 0 | V36: 0 | X36: =IF(J36=0,C36,"CHECK C4") -> 778.7 | Y36: =IF(K36=0,D36,X36*R$41) -> 1456.6 | Z36: =IF(L36=0,E36,Y36*S$41) -> 1941.2 | AA36: =IF(M36=0,F36,Z36*T$41) -> 2119.6
B37: 2023 | C37: =IF('Raw Data'!C23="","",'Raw Data'!C23) -> 757.7 | D37: =IF('Raw Data'!D23="","",'Raw Data'!D23) -> 1549 | E37: =IF('Raw Data'!E23="","",'Raw Data'!E23) -> 1982.1 | J37: =IF(ISNUMBER(C37),0,1) -> 0 | K37: =IF(NOT(ISNUMBER(D37)),1,IF(NOT(ISNUMBER(C37)),0,IF(OR(D37<=C37,IF(C37<=0,TRUE(),D37/C37>Val_ratio_max)),1,0))) -> 0 | L37: =IF(NOT(ISNUMBER(E37)),1,IF(NOT(ISNUMBER(D37)),0,IF(OR(E37<=D37,IF(D37<=0,TRUE(),E37/D37>Val_ratio_max)),1,0))) -> 0 | M37: 0 | N37: 0 | O37: 0 | Q37: =IF(J37=1,0,IF(ISNUMBER(C37),C37,0)) -> 757.7 | R37: =IF(K37=1,0,IF(ISNUMBER(D37),D37,0)) -> 1549 | S37: =IF(L37=1,0,IF(ISNUMBER(E37),E37,0)) -> 1982.1 | T37: 0 | U37: 0 | V37: 0 | X37: =IF(J37=0,C37,"CHECK C4") -> 757.7 | Y37: =IF(K37=0,D37,X37*R$41) -> 1549 | Z37: =IF(L37=0,E37,Y37*S$41) -> 1982.1
B38: 2024 | C38: =IF('Raw Data'!C24="","",'Raw Data'!C24) -> 960.5 | D38: =IF('Raw Data'!D24="","",'Raw Data'!D24) -> 1694.4 | J38: =IF(ISNUMBER(C38),0,1) -> 0 | K38: =IF(NOT(ISNUMBER(D38)),1,IF(NOT(ISNUMBER(C38)),0,IF(OR(D38<=C38,IF(C38<=0,TRUE(),D38/C38>Val_ratio_max)),1,0))) -> 0 | L38: 0 | M38: 0 | N38: 0 | O38: 0 | Q38: =IF(J38=1,0,IF(ISNUMBER(C38),C38,0)) -> 960.5 | R38: =IF(K38=1,0,IF(ISNUMBER(D38),D38,0)) -> 1694.4 | S38: 0 | T38: 0 | U38: 0 | V38: 0 | X38: =IF(J38=0,C38,"CHECK C4") -> 960.5 | Y38: =IF(K38=0,D38,X38*R$41) -> 1694.4
B39: 2025 | C39: =IF('Raw Data'!C25="","",'Raw Data'!C25) -> 907 | J39: =IF(ISNUMBER(C39),0,1) -> 0 | K39: 0 | L39: 0 | M39: 0 | N39: 0 | O39: 0 | Q39: =IF(J39=1,0,IF(ISNUMBER(C39),C39,0)) -> 907 | R39: 0 | S39: 0 | T39: 0 | U39: 0 | V39: 0 | X39: =IF(J39=0,C39,"CHECK C4") -> 907
Q40: Volume-weighted average link ratio, computed from clean cells only (a cell pair is used only where both cells are unflagged, numeric and inside the triangle) | R40: 12-24 | S40: 24-36 | T40: 36-48 | U40: 48-60 | V40: 60-72
B41: Clean link ratio | J41: Cells flagged | M41: =SUM(J34:O39) -> 1 | R41: =SUMPRODUCT((R34:R39>0)*(Q34:Q39>0)*R34:R39)/SUMPRODUCT((R34:R39>0)*(Q34:Q39>0)*Q34:Q39) -> 1.9128163 | S41: =SUMPRODUCT((S34:S39>0)*(R34:R39>0)*S34:S39)/SUMPRODUCT((S34:S39>0)*(R34:R39>0)*R34:R39) -> 1.2790261 | T41: =SUMPRODUCT((T34:T39>0)*(S34:S39>0)*T34:T39)/SUMPRODUCT((T34:T39>0)*(S34:S39>0)*S34:S39) -> 1.1035295 | U41: =SUMPRODUCT((U34:U39>0)*(T34:T39>0)*U34:U39)/SUMPRODUCT((U34:U39>0)*(T34:T39>0)*T34:T39) -> 1.0803052 | V41: =SUMPRODUCT((V34:V39>0)*(U34:U39>0)*V34:V39)/SUMPRODUCT((V34:V39>0)*(U34:U39>0)*U34:U39) -> 1.02
B47: Group C - Specialist haulage
C48: Raw as received (£000) | J48: Defect flags (1 = flagged) | Q48: Clean numeric values (£000) | X48: Validated cumulative paid (£000)
B49: Accident year | C49: 12 | D49: 24 | E49: 36 | F49: 48 | G49: 60 | H49: 72 | J49: 12 | K49: 24 | L49: 36 | M49: 48 | N49: 60 | O49: 72 | Q49: 12 | R49: 24 | S49: 36 | T49: 48 | U49: 60 | V49: 72 | X49: 12 | Y49: 24 | Z49: 36 | AA49: 48 | AB49: 60 | AC49: 72
B50: 2020 | C50: =IF('Raw Data'!C30="","",'Raw Data'!C30) -> 321.3 | D50: =IF('Raw Data'!D30="","",'Raw Data'!D30) -> 6865 | E50: =IF('Raw Data'!E30="","",'Raw Data'!E30) -> 959.7 | F50: =IF('Raw Data'!F30="","",'Raw Data'!F30) -> 1162.1 | G50: =IF('Raw Data'!G30="","",'Raw Data'!G30) -> 1241.6 | H50: =IF('Raw Data'!H30="","",'Raw Data'!H30) -> 1300.2 | J50: =IF(ISNUMBER(C50),0,1) -> 0 | K50: =IF(NOT(ISNUMBER(D50)),1,IF(NOT(ISNUMBER(C50)),0,IF(OR(D50<=C50,IF(C50<=0,TRUE(),D50/C50>Val_ratio_max)),1,0))) -> 1 | L50: =IF(NOT(ISNUMBER(E50)),1,IF(NOT(ISNUMBER(D50)),0,IF(OR(E50<=D50,IF(D50<=0,TRUE(),E50/D50>Val_ratio_max)),1,0))) -> 1 | M50: =IF(NOT(ISNUMBER(F50)),1,IF(NOT(ISNUMBER(E50)),0,IF(OR(F50<=E50,IF(E50<=0,TRUE(),F50/E50>Val_ratio_max)),1,0))) -> 0 | N50: =IF(NOT(ISNUMBER(G50)),1,IF(NOT(ISNUMBER(F50)),0,IF(OR(G50<=F50,IF(F50<=0,TRUE(),G50/F50>Val_ratio_max)),1,0))) -> 0 | O50: =IF(NOT(ISNUMBER(H50)),1,IF(NOT(ISNUMBER(G50)),0,IF(OR(H50<=G50,IF(G50<=0,TRUE(),H50/G50>Val_ratio_max)),1,0))) -> 0 | Q50: =IF(J50=1,0,IF(ISNUMBER(C50),C50,0)) -> 321.3 | R50: =IF(K50=1,0,IF(ISNUMBER(D50),D50,0)) -> 0 | S50: =IF(L50=1,0,IF(ISNUMBER(E50),E50,0)) -> 0 | T50: =IF(M50=1,0,IF(ISNUMBER(F50),F50,0)) -> 1162.1 | U50: =IF(N50=1,0,IF(ISNUMBER(G50),G50,0)) -> 1241.6 | V50: =IF(O50=1,0,IF(ISNUMBER(H50),H50,0)) -> 1300.2 | X50: =IF(J50=0,C50,"CHECK C4") -> 321.3 | Y50: =IF(K50=0,D50,X50*R$57) -> 672.30574 | Z50: =IF(L50=0,E50,Y50*S$57) -> 901.80259 | AA50: =IF(M50=0,F50,Z50*T$57) -> 1162.1 | AB50: =IF(N50=0,G50,AA50*U$57) -> 1241.6 | AC50: =IF(O50=0,H50,AB50*V$57) -> 1300.2
B51: 2021 | C51: =IF('Raw Data'!C31="","",'Raw Data'!C31) -> 388 | D51: =IF('Raw Data'!D31="","",'Raw Data'!D31) -> 799.2 | E51: =IF('Raw Data'!E31="","",'Raw Data'!E31) -> 1092 | F51: =IF('Raw Data'!F31="","",'Raw Data'!F31) -> 1318.5 | G51: =IF('Raw Data'!G31="","",'Raw Data'!G31) -> 1409.9 | J51: =IF(ISNUMBER(C51),0,1) -> 0 | K51: =IF(NOT(ISNUMBER(D51)),1,IF(NOT(ISNUMBER(C51)),0,IF(OR(D51<=C51,IF(C51<=0,TRUE(),D51/C51>Val_ratio_max)),1,0))) -> 0 | L51: =IF(NOT(ISNUMBER(E51)),1,IF(NOT(ISNUMBER(D51)),0,IF(OR(E51<=D51,IF(D51<=0,TRUE(),E51/D51>Val_ratio_max)),1,0))) -> 0 | M51: =IF(NOT(ISNUMBER(F51)),1,IF(NOT(ISNUMBER(E51)),0,IF(OR(F51<=E51,IF(E51<=0,TRUE(),F51/E51>Val_ratio_max)),1,0))) -> 0 | N51: =IF(NOT(ISNUMBER(G51)),1,IF(NOT(ISNUMBER(F51)),0,IF(OR(G51<=F51,IF(F51<=0,TRUE(),G51/F51>Val_ratio_max)),1,0))) -> 0 | O51: 0 | Q51: =IF(J51=1,0,IF(ISNUMBER(C51),C51,0)) -> 388 | R51: =IF(K51=1,0,IF(ISNUMBER(D51),D51,0)) -> 799.2 | S51: =IF(L51=1,0,IF(ISNUMBER(E51),E51,0)) -> 1092 | T51: =IF(M51=1,0,IF(ISNUMBER(F51),F51,0)) -> 1318.5 | U51: =IF(N51=1,0,IF(ISNUMBER(G51),G51,0)) -> 1409.9 | V51: 0 | X51: =IF(J51=0,C51,"CHECK C4") -> 388 | Y51: =IF(K51=0,D51,X51*R$57) -> 799.2 | Z51: =IF(L51=0,E51,Y51*S$57) -> 1092 | AA51: =IF(M51=0,F51,Z51*T$57) -> 1318.5 | AB51: =IF(N51=0,G51,AA51*U$57) -> 1409.9
B52: 2022 | C52: =IF('Raw Data'!C32="","",'Raw Data'!C32) -> 457.3 | D52: =IF('Raw Data'!D32="","",'Raw Data'!D32) -> 1002.9 | E52: =IF('Raw Data'!E32="","",'Raw Data'!E32) -> 1336.5 | F52: =IF('Raw Data'!F32="","",'Raw Data'!F32) -> 1598 | J52: =IF(ISNUMBER(C52),0,1) -> 0 | K52: =IF(NOT(ISNUMBER(D52)),1,IF(NOT(ISNUMBER(C52)),0,IF(OR(D52<=C52,IF(C52<=0,TRUE(),D52/C52>Val_ratio_max)),1,0))) -> 0 | L52: =IF(NOT(ISNUMBER(E52)),1,IF(NOT(ISNUMBER(D52)),0,IF(OR(E52<=D52,IF(D52<=0,TRUE(),E52/D52>Val_ratio_max)),1,0))) -> 0 | M52: =IF(NOT(ISNUMBER(F52)),1,IF(NOT(ISNUMBER(E52)),0,IF(OR(F52<=E52,IF(E52<=0,TRUE(),F52/E52>Val_ratio_max)),1,0))) -> 0 | N52: 0 | O52: 0 | Q52: =IF(J52=1,0,IF(ISNUMBER(C52),C52,0)) -> 457.3 | R52: =IF(K52=1,0,IF(ISNUMBER(D52),D52,0)) -> 1002.9 | S52: =IF(L52=1,0,IF(ISNUMBER(E52),E52,0)) -> 1336.5 | T52: =IF(M52=1,0,IF(ISNUMBER(F52),F52,0)) -> 1598 | U52: 0 | V52: 0 | X52: =IF(J52=0,C52,"CHECK C4") -> 457.3 | Y52: =IF(K52=0,D52,X52*R$57) -> 1002.9 | Z52: =IF(L52=0,E52,Y52*S$57) -> 1336.5 | AA52: =IF(M52=0,F52,Z52*T$57) -> 1598
B53: 2023 | C53: =IF('Raw Data'!C33="","",'Raw Data'!C33) -> 450.7 | D53: =IF('Raw Data'!D33="","",'Raw Data'!D33) -> 947.8 | E53: =IF('Raw Data'!E33="","",'Raw Data'!E33) -> 1260.1 | J53: =IF(ISNUMBER(C53),0,1) -> 0 | K53: =IF(NOT(ISNUMBER(D53)),1,IF(NOT(ISNUMBER(C53)),0,IF(OR(D53<=C53,IF(C53<=0,TRUE(),D53/C53>Val_ratio_max)),1,0))) -> 0 | L53: =IF(NOT(ISNUMBER(E53)),1,IF(NOT(ISNUMBER(D53)),0,IF(OR(E53<=D53,IF(D53<=0,TRUE(),E53/D53>Val_ratio_max)),1,0))) -> 0 | M53: 0 | N53: 0 | O53: 0 | Q53: =IF(J53=1,0,IF(ISNUMBER(C53),C53,0)) -> 450.7 | R53: =IF(K53=1,0,IF(ISNUMBER(D53),D53,0)) -> 947.8 | S53: =IF(L53=1,0,IF(ISNUMBER(E53),E53,0)) -> 1260.1 | T53: 0 | U53: 0 | V53: 0 | X53: =IF(J53=0,C53,"CHECK C4") -> 450.7 | Y53: =IF(K53=0,D53,X53*R$57) -> 947.8 | Z53: =IF(L53=0,E53,Y53*S$57) -> 1260.1
...

Sheet Parameters
B1: Parameters and Assumptions
B2: Satisfies Part 1 requirement 2. Blue cells are inputs; yellow fill marks a judgemental assumption. Column G gives the defined name where one exists; column H gives the source or rationale.
B5: Table 5: Rating group definition and exposure
B6: Descriptive parameters for the three rating groups that make up the Commercial Motor account.
B7: Parameter | C7: Group A | D7: Group B | E7: Group C | G7: Defined name | H7: Source / rationale
B8: Vehicles on cover at 31 December 2025 | C8: 2840 | D8: 1120 | E8: 410 | H8: Policy administration system, in-force listing.
B9: Average sum insured per vehicle (£000) | C9: 28 | D9: 64 | E9: 95 | H9: Policy administration system, weighted by exposure.
B10: Salvage and subrogation recoveries netted in data | C10: No | D10: No | E10: No | H10: Confirmed with claims manager; supports validation rule R2.
B11: Expense ratio (% of earned premium) | C11: 0.27 | D11: 0.255 | E11: 0.29 | G11: Exp_ratio | H11: Management accounts, three-year average. Used for the combined ratio only.
B14: Table 6: Economic and expense assumptions
B15: Applied uniformly across the three rating groups unless stated otherwise.
B16: Parameter | C16: Value | G16: Defined name | H16: Source / rationale
B17: Past claims severity trend (per annum) | C17: 0.055 | G17: Loss_trend | H17: Internal severity study over accident years 2018-2025, corroborated by ABI motor claims inflation indices. Judgemental.
B18: Cost of capital / discount rate (per annum) | C18: 0.05 | G18: Disc_rate | H18: Board-approved cost of capital. Used for the discounted view only.
B21: Table 7: A priori loss ratio and credibility parameters
B22: Used to derive the a priori loss ratio underlying the Expected Claims and Bornhuetter-Ferguson bases.
B23: Parameter | C23: Group A | D23: Group B | E23: Group C | G23: Defined name | H23: Source / rationale
B24: Business plan ultimate loss ratio (2025 rate and cost level) | C24: 0.62 | D24: 0.7 | E24: 0.76 | G24: Plan_LR | H24: 2026 business plan approved by the Board, being the complement of credibility.
B25: Full credibility standard (number of claims) | C25: 1082 | D25: 1082 | E25: 1082 | G25: Cred_full | H25: Limited fluctuation standard for 90% probability of being within 5% of expected claim frequency.
B26: Accident years used for the experience indication | C26: 3 | D26: 3 | E26: 3 | G26: Cred_mature | H26: The three oldest accident years, being the most fully developed. Judgemental.
B29: Table 8: Extension scenario parameters
B30: Instruction of the Chief Actuary dated 12 February 2026. These parameters drive the extension scenario only; setting the shock to zero and the tail factors to 1.000 reproduces the base scenarios exactly.
B31: Parameter | C31: Group A | D31: Group B | E31: Group C | G31: Defined name | H31: Source / rationale
B32: Tail factor beyond 72 months development | C32: 1.012 | D32: 1.034 | E32: 1.055 | G32: Ext_tail | H32: Benchmarked against the ABI market development pattern for commercial motor. Judgemental.
B33: Average lag of tail payments beyond 72 months (years) | C33: 3 | G33: Ext_taillag | H33: Judgemental, reflecting the settlement profile of large bodily injury claims.
B34: Additional claims inflation on unpaid amounts (per annum) | C34: 0.04 | G34: Ext_shock | H34: Chief Actuary instruction, reflecting the Ogden discount rate review and observed care-cost inflation. Judgemental.
B37: Table 9: Adverse Development Cover terms
B38: Indicative terms quoted by the reinsurer on 3 February 2026 for a cover attaching to the booked reserve for the whole account.
B39: Parameter | C39: Value | G39: Defined name | H39: Source / rationale
B40: Attachment point (% of booked reserve) | C40: 1.05 | G40: ADC_att | H40: Reinsurer quotation.
B41: Exhaustion point (% of booked reserve) | C41: 1.3 | G41: ADC_exh | H41: Reinsurer quotation.
B42: Rate on line (% of limit) | C42: 0.12 | G42: ADC_rol | H42: Reinsurer quotation.
B45: Table 10: Validation thresholds and modelling conventions
B46: Thresholds used by the validation rules on the Data Validation sheet, and conventions adopted throughout the model.
B47: Parameter | C47: Value | G47: Defined name | H47: Source / rationale
B48: Maximum plausible link ratio (outlier bound) | C48: 4 | G48: Val_ratio_max | H48: Set well above the largest observed 12-24 month factor of about 2.1, so that only gross keying errors are caught.
B49: Minimum plausible annual rate change | C49: -0.25 | G49: Val_rate_min | H49: Judgemental bound on the underwriting rate monitoring return.
B50: Maximum plausible annual rate change | C50: 0.25 | G50: Val_rate_max | H50: Judgemental bound on the underwriting rate monitoring return.
B51: Development ages modelled (months) | C51: 72 | H51: Six development periods observed; beyond this the tail factor applies.
B52: Timing convention for payments within a period | C52: End of period | H52: Simplifying convention; stated as an assumption in the Audit Trail.

Sheet Dev Factors
B1: Stage 1 - Development factors
B2: Age-to-age factors are calculated from the validated cumulative paid triangles. The selection is the volume-weighted all-year average, which gives greater weight to the larger and more stable accident years. Base scenarios carry no tail; the tail is introduced only in the extension scenario.
B5: Group A - Light commercial vehicles
B6: Individual age-to-age factors
B7: Accident year | C7: 12-24 | D7: 24-36 | E7: 36-48 | F7: 48-60 | G7: 60-72
B8: 2020 | C8: ='Data Validation'!Y18/'Data Validation'!X18 -> 1.8271052 | D8: ='Data Validation'!Z18/'Data Validation'!Y18 -> 1.1892554 | E8: ='Data Validation'!AA18/'Data Validation'!Z18 -> 1.0879042 | F8: ='Data Validation'!AB18/'Data Validation'!AA18 -> 1.0324086 | G8: ='Data Validation'!AC18/'Data Validation'!AB18 -> 1.0374904
B9: 2021 | C9: ='Data Validation'!Y19/'Data Validation'!X19 -> 1.8420389 | D9: ='Data Validation'!Z19/'Data Validation'!Y19 -> 1.2015747 | E9: ='Data Validation'!AA19/'Data Validation'!Z19 -> 1.1046534 | F9: ='Data Validation'!AB19/'Data Validation'!AA19 -> 1.0478422
B10: 2022 | C10: ='Data Validation'!Y20/'Data Validation'!X20 -> 1.4710234 | D10: ='Data Validation'!Z20/'Data Validation'!Y20 -> 1.2311167 | E10: ='Data Validation'!AA20/'Data Validation'!Z20 -> 1.0963157
B11: 2023 | C11: ='Data Validation'!Y21/'Data Validation'!X21 -> 1.6600909 | D11: ='Data Validation'!Z21/'Data Validation'!Y21 -> 1.2475035
B12: 2024 | C12: ='Data Validation'!Y22/'Data Validation'!X22 -> 1.6196431
B13: Development age (months) | C13: 12 | D13: 24 | E13: 36 | F13: 48 | G13: 60 | H13: 72
B14: Selected LDF (volume-weighted, all years) | C14: =SUM('Data Validation'!Y18:Y22)/SUM('Data Validation'!X18:X22) -> 1.6600909 | D14: =SUM('Data Validation'!Z18:Z21)/SUM('Data Validation'!Y18:Y21) -> 1.2196486 | E14: =SUM('Data Validation'!AA18:AA20)/SUM('Data Validation'!Z18:Z20) -> 1.0963157 | F14: =SUM('Data Validation'!AB18:AB19)/SUM('Data Validation'!AA18:AA19) -> 1.0402184 | G14: =SUM('Data Validation'!AC18:AC18)/SUM('Data Validation'!AB18:AB18) -> 1.0374904
B15: CDF to 72 months - base (no tail) | C15: =D15*C14 -> 2.395581 | D15: =E15*D14 -> 1.443042 | E15: =F15*E14 -> 1.1831621 | F15: =G15*F14 -> 1.0792166 | G15: =H15*G14 -> 1.0374904 | H15: 1
B16: % of ultimate paid at each age - base | C16: =1/C15 -> 0.41743527 | D16: =1/D15 -> 0.6929805 | E16: =1/E15 -> 0.84519271 | F16: =1/F15 -> 0.92659806 | G16: =1/G15 -> 0.96386434 | H16: =1/H15 -> 1
B17: Check: selected factors are non-increasing and at least 1.000 | H17: =IF(AND(MIN(C14:G14)>=1,SUMPRODUCT(--(C14:F14<D14:G14))=0),"OK","REVIEW") -> OK
B20: Group B - Heavy goods vehicles
B21: Individual age-to-age factors
B22: Accident year | C22: 12-24 | D22: 24-36 | E22: 36-48 | F22: 48-60 | G22: 60-72
B23: 2020 | C23: ='Data Validation'!Y34/'Data Validation'!X34 -> 1.9028064 | D23: ='Data Validation'!Z34/'Data Validation'!Y34 -> 1.2131489 | E23: ='Data Validation'!AA34/'Data Validation'!Z34 -> 1.1190329 | F23: ='Data Validation'!AB34/'Data Validation'!AA34 -> 1.1140437 | G23: ='Data Validation'!AC34/'Data Validation'!AB34 -> 1.02
B24: 2021 | C24: ='Data Validation'!Y35/'Data Validation'!X35 -> 2.0337441 | D24: ='Data Validation'!Z35/'Data Validation'!Y35 -> 1.2790261 | E24: ='Data Validation'!AA35/'Data Validation'!Z35 -> 1.1284353 | F24: ='Data Validation'!AB35/'Data Validation'!AA35 -> 1.0528315
B25: 2022 | C25: ='Data Validation'!Y36/'Data Validation'!X36 -> 1.8705535 | D25: ='Data Validation'!Z36/'Data Validation'!Y36 -> 1.3326926 | E25: ='Data Validation'!AA36/'Data Validation'!Z36 -> 1.0919019
B26: 2023 | C26: ='Data Validation'!Y37/'Data Validation'!X37 -> 2.0443447 | D26: ='Data Validation'!Z37/'Data Validation'!Y37 -> 1.2795997
B27: 2024 | C27: ='Data Validation'!Y38/'Data Validation'!X38 -> 1.7640812
B28: Development age (months) | C28: 12 | D28: 24 | E28: 36 | F28: 48 | G28: 60 | H28: 72
B29: Selected LDF (volume-weighted, all years) | C29: =SUM('Data Validation'!Y34:Y38)/SUM('Data Validation'!X34:X38) -> 1.9128163 | D29: =SUM('Data Validation'!Z34:Z37)/SUM('Data Validation'!Y34:Y37) -> 1.2790261 | E29: =SUM('Data Validation'!AA34:AA36)/SUM('Data Validation'!Z34:Z36) -> 1.1120705 | F29: =SUM('Data Validation'!AB34:AB35)/SUM('Data Validation'!AA34:AA35) -> 1.0803052 | G29: =SUM('Data Validation'!AC34:AC34)/SUM('Data Validation'!AB34:AB34) -> 1.02
B30: CDF to 72 months - base (no tail) | C30: =D30*C29 -> 2.9980001 | D30: =E30*D29 -> 1.5673225 | E30: =F30*E29 -> 1.2254031 | F30: =G30*F29 -> 1.1019113 | G30: =H30*G29 -> 1.02 | H30: 1
B31: % of ultimate paid at each age - base | C31: =1/C30 -> 0.33355569 | D31: =1/D30 -> 0.63803078 | E31: =1/E30 -> 0.81605801 | F31: =1/F30 -> 0.90751402 | G31: =1/G30 -> 0.98039216 | H31: =1/H30 -> 1
B32: Check: selected factors are non-increasing and at least 1.000 | H32: =IF(AND(MIN(C29:G29)>=1,SUMPRODUCT(--(C29:F29<D29:G29))=0),"OK","REVIEW") -> OK
B35: Group C - Specialist haulage
B36: Individual age-to-age factors
B37: Accident year | C37: 12-24 | D37: 24-36 | E37: 36-48 | F37: 48-60 | G37: 60-72
B38: 2020 | C38: ='Data Validation'!Y50/'Data Validation'!X50 -> 2.0924548 | D38: ='Data Validation'!Z50/'Data Validation'!Y50 -> 1.3413579 | E38: ='Data Validation'!AA50/'Data Validation'!Z50 -> 1.2886412 | F38: ='Data Validation'!AB50/'Data Validation'!AA50 -> 1.0684106 | G38: ='Data Validation'!AC50/'Data Validation'!AB50 -> 1.0471972
B39: 2021 | C39: ='Data Validation'!Y51/'Data Validation'!X51 -> 2.0597938 | D39: ='Data Validation'!Z51/'Data Validation'!Y51 -> 1.3663664 | E39: ='Data Validation'!AA51/'Data Validation'!Z51 -> 1.2074176 | F39: ='Data Validation'!AB51/'Data Validation'!AA51 -> 1.0693212
B40: 2022 | C40: ='Data Validation'!Y52/'Data Validation'!X52 -> 2.1930899 | D40: ='Data Validation'!Z52/'Data Validation'!Y52 -> 1.3326354 | E40: ='Data Validation'!AA52/'Data Validation'!Z52 -> 1.1956603
B41: 2023 | C41: ='Data Validation'!Y53/'Data Validation'!X53 -> 2.102951 | D41: ='Data Validation'!Z53/'Data Validation'!Y53 -> 1.3294999
B42: 2024 | C42: ='Data Validation'!Y54/'Data Validation'!X54 -> 2.0150437
B43: Development age (months) | C43: 12 | D43: 24 | E43: 36 | F43: 48 | G43: 60 | H43: 72
B44: Selected LDF (volume-weighted, all years) | C44: =SUM('Data Validation'!Y50:Y54)/SUM('Data Validation'!X50:X54) -> 2.0924548 | D44: =SUM('Data Validation'!Z50:Z53)/SUM('Data Validation'!Y50:Y53) -> 1.3413579 | E44: =SUM('Data Validation'!AA50:AA52)/SUM('Data Validation'!Z50:Z52) -> 1.2246935 | F44: =SUM('Data Validation'!AB50:AB51)/SUM('Data Validation'!AA50:AA51) -> 1.0688946 | G44: =SUM('Data Validation'!AC50:AC50)/SUM('Data Validation'!AB50:AB50) -> 1.0471972
B45: CDF to 72 months - base (no tail) | C45: =D45*C44 -> 3.8476142 | D45: =E45*D44 -> 1.838804 | E45: =F45*E44 -> 1.3708526 | F45: =G45*F44 -> 1.1193434 | G45: =H45*G44 -> 1.0471972 | H45: 1
B46: % of ultimate paid at each age - base | C46: =1/C45 -> 0.25990132 | D46: =1/D45 -> 0.54383176 | E46: =1/E45 -> 0.72947301 | F46: =1/F45 -> 0.89338087 | G46: =1/G45 -> 0.95493001 | H46: =1/H45 -> 1
...

Sheet S1 Chain Ladder
B1: Base Scenario 1 - Chain Ladder
B2: Ultimate claims are the latest cumulative paid amount grossed up by the cumulative development factor for the corresponding development age. The method uses only the experience of the account and makes no use of premium.
B5: Group A - Light commercial vehicles
B6: Accident year | C6: Development age (months) | D6: Paid to date (£000) | E6: CDF | F6: Ultimate claims (£000) | G6: Reserve (£000) | H6: % paid to date
B7: 2020 | C7: 72 | D7: ='Data Validation'!AC18 -> 2432.5 | E7: ='Dev Factors'!H15 -> 1 | F7: =D7*E7 -> 2432.5 | G7: =F7-D7 -> 0 | H7: =D7/F7 -> 1
B8: 2021 | C8: 60 | D8: ='Data Validation'!AB19 -> 2437.7 | E8: ='Dev Factors'!G15 -> 1.0374904 | F8: =D8*E8 -> 2529.0904 | G8: =F8-D8 -> 91.390357 | H8: =D8/F8 -> 0.96386434
B9: 2022 | C9: 48 | D9: ='Data Validation'!AA20 -> 2898.3299 | E9: ='Dev Factors'!F15 -> 1.0792166 | F9: =D9*E9 -> 3127.9257 | G9: =F9-D9 -> 229.59581 | H9: =D9/F9 -> 0.92659806
B10: 2023 | C10: 36 | D10: ='Data Validation'!Z21 -> 2705.1 | E10: ='Dev Factors'!E15 -> 1.1831621 | F10: =D10*E10 -> 3200.5719 | G10: =F10-D10 -> 495.47185 | H10: =D10/F10 -> 0.84519271
B11: 2024 | C11: 24 | D11: ='Data Validation'!Y22 -> 2305.4 | E11: ='Dev Factors'!D15 -> 1.443042 | F11: =D11*E11 -> 3326.7891 | G11: =F11-D11 -> 1021.3891 | H11: =D11/F11 -> 0.6929805
B12: 2025 | C12: 12 | D12: ='Data Validation'!X23 -> 1525.9 | E12: ='Dev Factors'!C15 -> 2.395581 | F12: =D12*E12 -> 3655.4171 | G12: =F12-D12 -> 2129.5171 | H12: =D12/F12 -> 0.41743527
B13: Total | D13: =D7+D8+D9+D10+D11+D12 -> 14304.93 | F13: =F7+F8+F9+F10+F11+F12 -> 18272.294 | G13: =G7+G8+G9+G10+G11+G12 -> 3967.3642 | H13: =D13/F13 -> 0.78287542
B14: Check: every ultimate is at least the paid to date | F14: =IF(SUMPRODUCT(--(F7:F12<D7:D12))=0,"OK","REVIEW") -> OK
B18: Group B - Heavy goods vehicles
B19: Accident year | C19: Development age (months) | D19: Paid to date (£000) | E19: CDF | F19: Ultimate claims (£000) | G19: Reserve (£000) | H19: % paid to date
B20: 2020 | C20: 72 | D20: ='Data Validation'!AC34 -> 1851.3 | E20: ='Dev Factors'!H30 -> 1 | F20: =D20*E20 -> 1851.3 | G20: =F20-D20 -> 0 | H20: =D20/F20 -> 1
B21: 2021 | C21: 60 | D21: ='Data Validation'!AB35 -> 2106.4 | E21: ='Dev Factors'!G30 -> 1.02 | F21: =D21*E21 -> 2148.528 | G21: =F21-D21 -> 42.128 | H21: =D21/F21 -> 0.98039216
B22: 2022 | C22: 48 | D22: ='Data Validation'!AA36 -> 2119.6 | E22: ='Dev Factors'!F30 -> 1.1019113 | F22: =D22*E22 -> 2335.6113 | G22: =F22-D22 -> 216.01129 | H22: =D22/F22 -> 0.90751402
B23: 2023 | C23: 36 | D23: ='Data Validation'!Z37 -> 1982.1 | E23: ='Dev Factors'!E30 -> 1.2254031 | F23: =D23*E23 -> 2428.8715 | G23: =F23-D23 -> 446.77146 | H23: =D23/F23 -> 0.81605801
B24: 2024 | C24: 24 | D24: ='Data Validation'!Y38 -> 1694.4 | E24: ='Dev Factors'!D30 -> 1.5673225 | F24: =D24*E24 -> 2655.6713 | G24: =F24-D24 -> 961.27126 | H24: =D24/F24 -> 0.63803078
B25: 2025 | C25: 12 | D25: ='Data Validation'!X39 -> 907 | E25: ='Dev Factors'!C30 -> 2.9980001 | F25: =D25*E25 -> 2719.1861 | G25: =F25-D25 -> 1812.1861 | H25: =D25/F25 -> 0.33355569
B26: Total | D26: =D20+D21+D22+D23+D24+D25 -> 10660.8 | F26: =F20+F21+F22+F23+F24+F25 -> 14139.168 | G26: =G20+G21+G22+G23+G24+G25 -> 3478.3681 | H26: =D26/F26 -> 0.75399061
B27: Check: every ultimate is at least the paid to date | F27: =IF(SUMPRODUCT(--(F20:F25<D20:D25))=0,"OK","REVIEW") -> OK
B31: Group C - Specialist haulage
B32: Accident year | C32: Development age (months) | D32: Paid to date (£000) | E32: CDF | F32: Ultimate claims (£000) | G32: Reserve (£000) | H32: % paid to date
B33: 2020 | C33: 72 | D33: ='Data Validation'!AC50 -> 1300.2 | E33: ='Dev Factors'!H45 -> 1 | F33: =D33*E33 -> 1300.2 | G33: =F33-D33 -> 0 | H33: =D33/F33 -> 1
B34: 2021 | C34: 60 | D34: ='Data Validation'!AB51 -> 1409.9 | E34: ='Dev Factors'!G45 -> 1.0471972 | F34: =D34*E34 -> 1476.4433 | G34: =F34-D34 -> 66.543283 | H34: =D34/F34 -> 0.95493001
B35: 2022 | C35: 48 | D35: ='Data Validation'!AA52 -> 1598 | E35: ='Dev Factors'!F45 -> 1.1193434 | F35: =D35*E35 -> 1788.7108 | G35: =F35-D35 -> 190.71078 | H35: =D35/F35 -> 0.89338087
B36: 2023 | C36: 36 | D36: ='Data Validation'!Z53 -> 1260.1 | E36: ='Dev Factors'!E45 -> 1.3708526 | F36: =D36*E36 -> 1727.4114 | G36: =F36-D36 -> 467.3114 | H36: =D36/F36 -> 0.72947301
B37: 2024 | C37: 24 | D37: ='Data Validation'!Y54 -> 991.2 | E37: ='Dev Factors'!D45 -> 1.838804 | F37: =D37*E37 -> 1822.6225 | G37: =F37-D37 -> 831.42248 | H37: =D37/F37 -> 0.54383176
B38: 2025 | C38: 12 | D38: ='Data Validation'!X55 -> 469 | E38: ='Dev Factors'!C45 -> 3.8476142 | F38: =D38*E38 -> 1804.5311 | G38: =F38-D38 -> 1335.5311 | H38: =D38/F38 -> 0.25990132
B39: Total | D39: =D33+D34+D35+D36+D37+D38 -> 7028.4 | F39: =F33+F34+F35+F36+F37+F38 -> 9919.919 | G39: =G33+G34+G35+G36+G37+G38 -> 2891.519 | H39: =D39/F39 -> 0.70851385
B40: Check: every ultimate is at least the paid to date | F40: =IF(SUMPRODUCT(--(F33:F38<D33:D38))=0,"OK","REVIEW") -> OK
B44: Portfolio total - all rating groups
D45: Paid to date (£000) | F45: Ultimate claims (£000) | G45: Reserve (£000)
B46: Total | D46: =D13+D26+D39 -> 31994.13 | F46: =F13+F26+F39 -> 42331.381 | G46: =G13+G26+G39 -> 10337.251

Sheet On-Level & Cred
B1: Stage 2 - On-levelling, loss trend and the credibility-weighted a priori loss ratio
B2: On-levelling restates historical earned premium to the rate level of the latest accident year; the loss trend restates historical claims to the latest cost level. Together they make the historical loss ratios comparable. The resulting experience indication is then blended with the business plan loss ratio using limited fluctuation credibility, giving the a priori loss ratio used by the Expected Claims and Bornhuetter-Ferguson bases.
B6: Group A - Light commercial vehicles
B7: Accident year | C7: Rate change (validated) | D7: Cumulative rate index | E7: On-level factor | F7: Earned premium (£000) | G7: On-level premium (£000) | H7: Trend factor | I7: Chain Ladder ultimate (£000) | J7: Trended ultimate (£000) | K7: Include in indication
B8: 2020 | C8: ='Data Validation'!K67 -> 0.02 | D8: =1+C8 -> 1.02 | E8: =$D$13/D8 -> 1.1677742 | F8: ='Raw Data'!C63 -> 4200 | G8: =F8*E8 -> 4904.6517 | H8: =(1+Loss_trend)^($B$13-B8) -> 1.30696 | I8: ='S1 Chain Ladder'!F7 -> 2432.5 | J8: =I8*H8 -> 3179.1802 | K8: =IF(B8<=$B$8+INDEX(Cred_mature,1)-1,1,0) -> 1
B9: 2021 | C9: ='Data Validation'!K68 -> -0.015 | D9: =D8*(1+C9) -> 1.0047 | E9: =$D$13/D9 -> 1.1855576 | F9: ='Raw Data'!C64 -> 4450 | G9: =F9*E9 -> 5275.7312 | H9: =(1+Loss_trend)^($B$13-B9) -> 1.2388247 | I9: ='S1 Chain Ladder'!F8 -> 2529.0904 | J9: =I9*H9 -> 3133.0995 | K9: =IF(B9<=$B$8+INDEX(Cred_mature,1)-1,1,0) -> 1
B10: 2022 | C10: ='Data Validation'!K69 -> 0.01 | D10: =D9*(1+C10) -> 1.014747 | E10: =$D$13/D10 -> 1.1738194 | F10: ='Raw Data'!C65 -> 4600 | G10: =F10*E10 -> 5399.5691 | H10: =(1+Loss_trend)^($B$13-B10) -> 1.1742414 | I10: ='S1 Chain Ladder'!F9 -> 3127.9257 | J10: =I10*H10 -> 3672.9398 | K10: =IF(B10<=$B$8+INDEX(Cred_mature,1)-1,1,0) -> 1
B11: 2023 | C11: ='Data Validation'!K70 -> 0.055 | D11: =D10*(1+C11) -> 1.0705581 | E11: =$D$13/D11 -> 1.112625 | F11: ='Raw Data'!C66 -> 4900 | G11: =F11*E11 -> 5451.8625 | H11: =(1+Loss_trend)^($B$13-B11) -> 1.113025 | I11: ='S1 Chain Ladder'!F10 -> 3200.5719 | J11: =I11*H11 -> 3562.3165 | K11: =IF(B11<=$B$8+INDEX(Cred_mature,1)-1,1,0) -> 0
B12: 2024 | C12: ='Data Validation'!K71 -> 0.075 | D12: =D11*(1+C12) -> 1.1508499 | E12: =$D$13/D12 -> 1.035 | F12: ='Raw Data'!C67 -> 5350 | G12: =F12*E12 -> 5537.25 | H12: =(1+Loss_trend)^($B$13-B12) -> 1.055 | I12: ='S1 Chain Ladder'!F11 -> 3326.7891 | J12: =I12*H12 -> 3509.7625 | K12: =IF(B12<=$B$8+INDEX(Cred_mature,1)-1,1,0) -> 0
B13: 2025 | C13: ='Data Validation'!K72 -> 0.035 | D13: =D12*(1+C13) -> 1.1911297 | E13: =$D$13/D13 -> 1 | F13: ='Raw Data'!C68 -> 5700 | G13: =F13*E13 -> 5700 | H13: =(1+Loss_trend)^($B$13-B13) -> 1 | I13: ='S1 Chain Ladder'!F12 -> 3655.4171 | J13: =I13*H13 -> 3655.4171 | K13: =IF(B13<=$B$8+INDEX(Cred_mature,1)-1,1,0) -> 0
B14: Derivation of the a priori loss ratio (at 2025 rate and cost level)
B15: Accident years used for the experience indication (oldest first) | C15: =SUM(K8:K13) -> 3
B16: Trended ultimate claims over those years (£000) | C16: =SUMPRODUCT($K$8:$K$13,$J$8:$J$13) -> 9985.2195
B17: On-level earned premium over those years (£000) | C17: =SUMPRODUCT($K$8:$K$13,$G$8:$G$13) -> 15579.952
B18: Experience indication - on-level ultimate loss ratio | C18: =C16/C17 -> 0.64090181
B19: Reported claims over those years | C19: =SUMPRODUCT($K$8:$K$13,'Raw Data'!C41:C46) -> 940
B20: Full credibility standard (claims) | C20: =INDEX(Cred_full,1) -> 1082
B21: Credibility factor Z = min(1, sqrt(n / n_full)) | C21: =MIN(1,SQRT(C19/C20)) -> 0.93207379
B22: Business plan loss ratio (complement of credibility) | C22: =INDEX(Plan_LR,1) -> 0.62
B23: A priori loss ratio = Z x indication + (1-Z) x plan | C23: =C21*C18+(1-C21)*C22 -> 0.63948203
B24: Check: Z lies in [0,1] and the a priori lies between the indication and the plan | C24: =IF(AND(C21>=0,C21<=1,C23>=MIN(C18,C22)-0.0001,C23<=MAX(C18,C22)+0.0001),"OK","REVIEW") -> OK
B25: Check: the latest accident year on-level factor equals 1.0000 | C25: =IF(ABS(E13-1)<0.000001,"OK","REVIEW") -> OK
B28: Group B - Heavy goods vehicles
B29: Accident year | C29: Rate change (validated) | D29: Cumulative rate index | E29: On-level factor | F29: Earned premium (£000) | G29: On-level premium (£000) | H29: Trend factor | I29: Chain Ladder ultimate (£000) | J29: Trended ultimate (£000) | K29: Include in indication
B30: 2020 | C30: ='Data Validation'!L67 -> 0.03 | D30: =1+C30 -> 1.03 | E30: =$D$35/D30 -> 1.1886748 | F30: ='Raw Data'!D63 -> 3100 | G30: =F30*E30 -> 3684.892 | H30: =(1+Loss_trend)^($B$35-B30) -> 1.30696 | I30: ='S1 Chain Ladder'!F20 -> 1851.3 | J30: =I30*H30 -> 2419.5751 | K30: =IF(B30<=$B$30+INDEX(Cred_mature,2)-1,1,0) -> 1
B31: 2021 | C31: ='Data Validation'!L68 -> -0.025 | D31: =D30*(1+C31) -> 1.00425 | E31: =$D$35/D31 -> 1.2191537 | F31: ='Raw Data'!D64 -> 3250 | G31: =F31*E31 -> 3962.2495 | H31: =(1+Loss_trend)^($B$35-B31) -> 1.2388247 | I31: ='S1 Chain Ladder'!F21 -> 2148.528 | J31: =I31*H31 -> 2661.6494 | K31: =IF(B31<=$B$30+INDEX(Cred_mature,2)-1,1,0) -> 1
B32: 2022 | C32: ='Data Validation'!L69 -> 0.005 | D32: =D31*(1+C32) -> 1.0092713 | E32: =$D$35/D32 -> 1.2130882 | F32: ='Raw Data'!D65 -> 3300 | G32: =F32*E32 -> 4003.1912 | H32: =(1+Loss_trend)^($B$35-B32) -> 1.1742414 | I32: ='S1 Chain Ladder'!F22 -> 2335.6113 | J32: =I32*H32 -> 2742.5714 | K32: =IF(B32<=$B$30+INDEX(Cred_mature,2)-1,1,0) -> 1
B33: 2023 | C33: ='Data Validation'!L70 -> 0.065 | D33: =D32*(1+C33) -> 1.0748739 | E33: =$D$35/D33 -> 1.13905 | F33: ='Raw Data'!D66 -> 3500 | G33: =F33*E33 -> 3986.675 | H33: =(1+Loss_trend)^($B$35-B33) -> 1.113025 | I33: ='S1 Chain Ladder'!F23 -> 2428.8715 | J33: =I33*H33 -> 2703.3947 | K33: =IF(B33<=$B$30+INDEX(Cred_mature,2)-1,1,0) -> 0
B34: 2024 | C34: ='Data Validation'!L71 -> 0.09 | D34: =D33*(1+C34) -> 1.1716125 | E34: =$D$35/D34 -> 1.045 | F34: ='Raw Data'!D67 -> 3850 | G34: =F34*E34 -> 4023.25 | H34: =(1+Loss_trend)^($B$35-B34) -> 1.055 | I34: ='S1 Chain Ladder'!F24 -> 2655.6713 | J34: =I34*H34 -> 2801.7332 | K34: =IF(B34<=$B$30+INDEX(Cred_mature,2)-1,1,0) -> 0
B35: 2025 | C35: ='Data Validation'!L72 -> 0.045 | D35: =D34*(1+C35) -> 1.2243351 | E35: =$D$35/D35 -> 1 | F35: ='Raw Data'!D68 -> 4150 | G35: =F35*E35 -> 4150 | H35: =(1+Loss_trend)^($B$35-B35) -> 1 | I35: ='S1 Chain Ladder'!F25 -> 2719.1861 | J35: =I35*H35 -> 2719.1861 | K35: =IF(B35<=$B$30+INDEX(Cred_mature,2)-1,1,0) -> 0
B36: Derivation of the a priori loss ratio (at 2025 rate and cost level)
B37: Accident years used for the experience indication (oldest first) | C37: =SUM(K30:K35) -> 3
B38: Trended ultimate claims over those years (£000) | C38: =SUMPRODUCT($K$30:$K$35,$J$30:$J$35) -> 7823.7959
B39: On-level earned premium over those years (£000) | C39: =SUMPRODUCT($K$30:$K$35,$G$30:$G$35) -> 11650.333
B40: Experience indication - on-level ultimate loss ratio | C40: =C38/C39 -> 0.67155128
B41: Reported claims over those years | C41: =SUMPRODUCT($K$30:$K$35,'Raw Data'!D41:D46) -> 450
B42: Full credibility standard (claims) | C42: =INDEX(Cred_full,2) -> 1082
B43: Credibility factor Z = min(1, sqrt(n / n_full)) | C43: =MIN(1,SQRT(C41/C42)) -> 0.64490037
B44: Business plan loss ratio (complement of credibility) | C44: =INDEX(Plan_LR,2) -> 0.7
B45: A priori loss ratio = Z x indication + (1-Z) x plan | C45: =C43*C40+(1-C43)*C44 -> 0.68165341
...

Sheet S2 Expected Claims
B1: Base Scenario 2 - Expected Claims
B2: Ultimate claims are the a priori loss ratio applied to on-level earned premium and then restated to the cost level of the accident year. The method ignores the claims reported to date and therefore gives a stable answer for immature years but can conflict with actual experience for mature years.
B3: Expected ultimate = On-level premium x A priori loss ratio / Trend factor.
B6: Group A - Light commercial vehicles
B7: Accident year | C7: On-level premium (£000) | D7: Trend factor | E7: Expected loss ratio | F7: Ultimate claims (£000) | G7: Paid to date (£000) | H7: Implied reserve (£000)
B8: 2020 | C8: ='On-Level & Cred'!G8 -> 4904.6517 | D8: ='On-Level & Cred'!H8 -> 1.30696 | E8: ='On-Level & Cred'!$C$23*'On-Level & Cred'!E8/D8 -> 0.57137986 | F8: =C8*'On-Level & Cred'!$C$23/D8 -> 2399.7954 | G8: ='S1 Chain Ladder'!D7 -> 2432.5 | H8: =F8-G8 -> -32.704599
B9: 2021 | C9: ='On-Level & Cred'!G9 -> 5275.7312 | D9: ='On-Level & Cred'!H9 -> 1.2388247 | E9: ='On-Level & Cred'!$C$23*'On-Level & Cred'!E9/D9 -> 0.61198553 | F9: =C9*'On-Level & Cred'!$C$23/D9 -> 2723.3356 | G9: ='S1 Chain Ladder'!D8 -> 2437.7 | H9: =F9-G9 -> 285.63562
B10: 2022 | C10: ='On-Level & Cred'!G10 -> 5399.5691 | D10: ='On-Level & Cred'!H10 -> 1.1742414 | E10: ='On-Level & Cred'!$C$23*'On-Level & Cred'!E10/D10 -> 0.63925221 | F10: =C10*'On-Level & Cred'!$C$23/D10 -> 2940.5602 | G10: ='S1 Chain Ladder'!D9 -> 2898.3299 | H10: =F10-G10 -> 42.230301
B11: 2023 | C11: ='On-Level & Cred'!G11 -> 5451.8625 | D11: ='On-Level & Cred'!H11 -> 1.113025 | E11: ='On-Level & Cred'!$C$23*'On-Level & Cred'!E11/D11 -> 0.63925221 | F11: =C11*'On-Level & Cred'!$C$23/D11 -> 3132.3359 | G11: ='S1 Chain Ladder'!D10 -> 2705.1 | H11: =F11-G11 -> 427.23585
B12: 2024 | C12: ='On-Level & Cred'!G12 -> 5537.25 | D12: ='On-Level & Cred'!H12 -> 1.055 | E12: ='On-Level & Cred'!$C$23*'On-Level & Cred'!E12/D12 -> 0.62735915 | F12: =C12*'On-Level & Cred'!$C$23/D12 -> 3356.3715 | G12: ='S1 Chain Ladder'!D11 -> 2305.4 | H12: =F12-G12 -> 1050.9715
B13: 2025 | C13: ='On-Level & Cred'!G13 -> 5700 | D13: ='On-Level & Cred'!H13 -> 1 | E13: ='On-Level & Cred'!$C$23*'On-Level & Cred'!E13/D13 -> 0.63948203 | F13: =C13*'On-Level & Cred'!$C$23/D13 -> 3645.0476 | G13: ='S1 Chain Ladder'!D12 -> 1525.9 | H13: =F13-G13 -> 2119.1476
B14: Total | F14: =SUM(F8:F13) -> 18197.446 | G14: =SUM(G8:G13) -> 14304.93 | H14: =SUM(H8:H13) -> 3892.5162
B15: Check: any accident year where the expected ultimate falls below the paid to date | F15: =IF(SUMPRODUCT(--(H8:H13<0))=0,"OK","SEE NOTE") -> SEE NOTE
B16: A negative implied reserve is a genuine feature of this method, not an error: it means actual paid claims have already exceeded the premium-based expectation. It is reported rather than floored, and is discussed in the Audit Trail.
B19: Group B - Heavy goods vehicles
B20: Accident year | C20: On-level premium (£000) | D20: Trend factor | E20: Expected loss ratio | F20: Ultimate claims (£000) | G20: Paid to date (£000) | H20: Implied reserve (£000)
B21: 2020 | C21: ='On-Level & Cred'!G30 -> 3684.892 | D21: ='On-Level & Cred'!H30 -> 1.30696 | E21: ='On-Level & Cred'!$C$45*'On-Level & Cred'!E30/D21 -> 0.61996103 | F21: =C21*'On-Level & Cred'!$C$45/D21 -> 1921.8792 | G21: ='S1 Chain Ladder'!D20 -> 1851.3 | H21: =F21-G21 -> 70.579183
B22: 2021 | C22: ='On-Level & Cred'!G31 -> 3962.2495 | D22: ='On-Level & Cred'!H31 -> 1.2388247 | E22: ='On-Level & Cred'!$C$45*'On-Level & Cred'!E31/D22 -> 0.67082962 | F22: =C22*'On-Level & Cred'!$C$45/D22 -> 2180.1963 | G22: ='S1 Chain Ladder'!D21 -> 2106.4 | H22: =F22-G22 -> 73.796277
B23: 2022 | C23: ='On-Level & Cred'!G32 -> 4003.1912 | D23: ='On-Level & Cred'!H32 -> 1.1742414 | E23: ='On-Level & Cred'!$C$45*'On-Level & Cred'!E32/D23 -> 0.70420423 | F23: =C23*'On-Level & Cred'!$C$45/D23 -> 2323.874 | G23: ='S1 Chain Ladder'!D22 -> 2119.6 | H23: =F23-G23 -> 204.27397
B24: 2023 | C24: ='On-Level & Cred'!G33 -> 3986.675 | D24: ='On-Level & Cred'!H33 -> 1.113025 | E24: ='On-Level & Cred'!$C$45*'On-Level & Cred'!E33/D24 -> 0.69759199 | F24: =C24*'On-Level & Cred'!$C$45/D24 -> 2441.5719 | G24: ='S1 Chain Ladder'!D23 -> 1982.1 | H24: =F24-G24 -> 459.47195
B25: 2024 | C25: ='On-Level & Cred'!G34 -> 4023.25 | D25: ='On-Level & Cred'!H34 -> 1.055 | E25: ='On-Level & Cred'!$C$45*'On-Level & Cred'!E34/D25 -> 0.67519224 | F25: =C25*'On-Level & Cred'!$C$45/D25 -> 2599.4901 | G25: ='S1 Chain Ladder'!D24 -> 1694.4 | H25: =F25-G25 -> 905.09014
B26: 2025 | C26: ='On-Level & Cred'!G35 -> 4150 | D26: ='On-Level & Cred'!H35 -> 1 | E26: ='On-Level & Cred'!$C$45*'On-Level & Cred'!E35/D26 -> 0.68165341 | F26: =C26*'On-Level & Cred'!$C$45/D26 -> 2828.8617 | G26: ='S1 Chain Ladder'!D25 -> 907 | H26: =F26-G26 -> 1921.8617
B27: Total | F27: =SUM(F21:F26) -> 14295.873 | G27: =SUM(G21:G26) -> 10660.8 | H27: =SUM(H21:H26) -> 3635.0732
B28: Check: any accident year where the expected ultimate falls below the paid to date | F28: =IF(SUMPRODUCT(--(H21:H26<0))=0,"OK","SEE NOTE") -> OK
B29: A negative implied reserve is a genuine feature of this method, not an error: it means actual paid claims have already exceeded the premium-based expectation. It is reported rather than floored, and is discussed in the Audit Trail.
B32: Group C - Specialist haulage
B33: Accident year | C33: On-level premium (£000) | D33: Trend factor | E33: Expected loss ratio | F33: Ultimate claims (£000) | G33: Paid to date (£000) | H33: Implied reserve (£000)
B34: 2020 | C34: ='On-Level & Cred'!G52 -> 2200.95 | D34: ='On-Level & Cred'!H52 -> 1.30696 | E34: ='On-Level & Cred'!$C$67*'On-Level & Cred'!E52/D34 -> 0.72537735 | F34: =C34*'On-Level & Cred'!$C$67/D34 -> 1305.6792 | G34: ='S1 Chain Ladder'!D33 -> 1300.2 | H34: =F34-G34 -> 5.4792351
B35: 2021 | C35: ='On-Level & Cred'!G53 -> 2395.0773 | D35: ='On-Level & Cred'!H53 -> 1.2388247 | E35: ='On-Level & Cred'!$C$67*'On-Level & Cred'!E53/D35 -> 0.78894135 | F35: =C35*'On-Level & Cred'!$C$67/D35 -> 1498.9886 | G35: ='S1 Chain Ladder'!D34 -> 1409.9 | H35: =F35-G35 -> 89.088561
B36: 2022 | C36: ='On-Level & Cred'!G54 -> 2471.7 | D36: ='On-Level & Cred'!H54 -> 1.1742414 | E36: ='On-Level & Cred'!$C$67*'On-Level & Cred'!E54/D36 -> 0.81601286 | F36: =C36*'On-Level & Cred'!$C$67/D36 -> 1632.0257 | G36: ='S1 Chain Ladder'!D35 -> 1598 | H36: =F36-G36 -> 34.025729
B37: 2023 | C37: ='On-Level & Cred'!G55 -> 2483.25 | D37: ='On-Level & Cred'!H55 -> 1.113025 | E37: ='On-Level & Cred'!$C$67*'On-Level & Cred'!E55/D37 -> 0.80457343 | F37: =C37*'On-Level & Cred'!$C$67/D37 -> 1729.8329 | G37: ='S1 Chain Ladder'!D36 -> 1260.1 | H37: =F37-G37 -> 469.73288
B38: 2024 | C38: ='On-Level & Cred'!G56 -> 2520 | D38: ='On-Level & Cred'!H56 -> 1.055 | E38: ='On-Level & Cred'!$C$67*'On-Level & Cred'!E56/D38 -> 0.77165906 | F38: =C38*'On-Level & Cred'!$C$67/D38 -> 1851.9818 | G38: ='S1 Chain Ladder'!D37 -> 991.2 | H38: =F38-G38 -> 860.78175
B39: 2025 | C39: ='On-Level & Cred'!G57 -> 2650 | D39: ='On-Level & Cred'!H57 -> 1 | E39: ='On-Level & Cred'!$C$67*'On-Level & Cred'!E57/D39 -> 0.77533363 | F39: =C39*'On-Level & Cred'!$C$67/D39 -> 2054.6341 | G39: ='S1 Chain Ladder'!D38 -> 469 | H39: =F39-G39 -> 1585.6341
B40: Total | F40: =SUM(F34:F39) -> 10073.142 | G40: =SUM(G34:G39) -> 7028.4 | H40: =SUM(H34:H39) -> 3044.7423
B41: Check: any accident year where the expected ultimate falls below the paid to date | F41: =IF(SUMPRODUCT(--(H34:H39<0))=0,"OK","SEE NOTE") -> OK
B42: A negative implied reserve is a genuine feature of this method, not an error: it means actual paid claims have already exceeded the premium-based expectation. It is reported rather than floored, and is discussed in the Audit Trail.
B45: Portfolio total - all rating groups
F46: Ultimate claims (£000) | G46: Paid to date (£000) | H46: Reserve (£000)
B47: Total | F47: =F14+F27+F40 -> 42566.462 | G47: =G14+G27+G40 -> 31994.13 | H47: =H14+H27+H40 -> 10572.332

Sheet S3 BF
B1: Base Scenario 3 - Bornhuetter-Ferguson
B2: The Bornhuetter-Ferguson ultimate accepts the claims already paid and adds the unpaid portion implied by the development pattern applied to the expected claims from Scenario 2. It therefore behaves like the Chain Ladder for mature years and like the Expected Claims method for immature years.
B3: BF ultimate = Paid to date + Expected ultimate x (1 - 1 / CDF).
B6: Group A - Light commercial vehicles
B7: Accident year | C7: Paid to date (£000) | D7: CDF | E7: % unpaid (1 - 1/CDF) | F7: Expected ultimate (£000) | G7: Ultimate claims (£000) | H7: Reserve (£000)
B8: 2020 | C8: ='S1 Chain Ladder'!D7 -> 2432.5 | D8: ='S1 Chain Ladder'!E7 -> 1 | E8: =1-1/D8 -> 0 | F8: ='S2 Expected Claims'!F8 -> 2399.7954 | G8: =C8+F8*E8 -> 2432.5 | H8: =G8-C8 -> 0
B9: 2021 | C9: ='S1 Chain Ladder'!D8 -> 2437.7 | D9: ='S1 Chain Ladder'!E8 -> 1.0374904 | E9: =1-1/D9 -> 0.036135663 | F9: ='S2 Expected Claims'!F9 -> 2723.3356 | G9: =C9+F9*E9 -> 2536.1095 | H9: =G9-C9 -> 98.409538
B10: 2022 | C10: ='S1 Chain Ladder'!D9 -> 2898.3299 | D10: ='S1 Chain Ladder'!E9 -> 1.0792166 | E10: =1-1/D10 -> 0.07340194 | F10: ='S2 Expected Claims'!F10 -> 2940.5602 | G10: =C10+F10*E10 -> 3114.1727 | H10: =G10-C10 -> 215.84282
